<?xml version="1.0" ?>
<robot name="two_wheeled_robot_with_pin">
  <link name="base_link">
    <visual>
      <geometry>
        <box size="0.5 0.4 0.1" />
      </geometry>
      <origin xyz="0 0.1 0" rpy="0 0 0" />
      <material name="green">
        <color rgba="0 1 0 1"/>
      </material>
    </visual>
    <collision>
      <geometry>
        <box size="0.5 0.4 0.1" />
      </geometry>
      <origin xyz="0 .1 0" rpy="0 0 0" />
    </collision>
    <inertial>
      <mass value="3.0"/>
      <origin xyz="0 0 0" rpy="0 0 0"/>
      <inertia ixx="0.01" ixy="0" ixz="0" iyy="0.01" iyz="0" izz="0.01"/>
    </inertial>
  </link>

  <link name="caster_wheel">
    <visual>
      <geometry>
        <sphere radius="0.04" /> <!-- Spherical caster -->
      </geometry>
      <origin xyz="0 0.08 -0.02" rpy="0 0 0" /> <!-- Positioned under the base -->
      <material name="black">
        <color rgba="0 0 0 1"/>
      </material>
    </visual>
    <collision>
      <geometry>
        <sphere radius="0.04" />
      </geometry>
      <origin xyz="0 0.08 -0.02" rpy="0 0 0" />
    </collision>
    <inertial>
      <mass value="0.1"/>
      <origin xyz="0 0 0" rpy="0 0 0"/>
      <inertia ixx="0.0001" ixy="0" ixz="0" iyy="0.0001" iyz="0" izz="0.0001"/>
    </inertial>
  </link>

  <link name="left_wheel">
    <visual>
      <geometry>
        <cylinder length="0.05" radius="0.1" />
      </geometry>
      <origin xyz="-0.15 0 0" rpy="0 1.57 0" />
      <material name="red">
        <color rgba="0 0 1 1"/>
      </material>
    </visual>
    <collision>
      <geometry>
        <cylinder length="0.05" radius="0.1" />
      </geometry>
      <origin xyz="-0.15 0 0" rpy="0 1.57 0" />
    </collision>
    <inertial>
      <mass value="0.2"/>
      <origin xyz="0 0 0" rpy="0 0 0"/>
      <inertia ixx="0.001" ixy="0" ixz="0" iyy="0.001" iyz="0" izz="0.001"/>
    </inertial>
  </link>

  <link name="right_wheel">
    <visual>
      <geometry>
        <cylinder length="0.05" radius="0.1" />
      </geometry>
      <origin xyz="0.15 0 0" rpy="0 1.57 0" />
      <material name="black">
        <color rgba="0 0 0 1"/>
      </material>
    </visual>
    <collision>
      <geometry>
        <cylinder length="0.05" radius="0.1" />
      </geometry>
      <origin xyz="0.15 0 0" rpy="0 1.57 0" />
    </collision>
    <inertial>
      <mass value="0.2"/>
      <origin xyz="0 0 0" rpy="0 0 0"/>
      <inertia ixx="0.001" ixy="0" ixz="0" iyy="0.001" iyz="0" izz="0.001"/>
    </inertial>
  </link>

<link name="pin">
  <visual>
    <geometry>
      <cylinder radius="0.02" length="0.2" />
    </geometry>
    <origin xyz="0 0.1 0" rpy="1.57 0 0" />
    <material name="silver">
      <color rgba="0.8 0.8 0.8 1"/>
    </material>
  </visual>
  <collision>
    <geometry>
      <cylinder radius="0.02" length="0.2" />
    </geometry>
    <origin xyz="0 0.1 0" rpy="1.57 0 0" />
  </collision>
  <inertial>
    <mass value="0.05"/>
    <origin xyz="0 0 0" rpy="0 0 0"/>
    <inertia ixx="0.0001" ixy="0" ixz="0" iyy="0.0001" iyz="0" izz="0.0001"/>
  </inertial>
</link>

<joint name="pin_joint" type="fixed">
  <parent link="base_link"/>
  <child link="pin"/>
  <origin xyz="0 0.25 0" rpy="0 0 0"/>
</joint>


  <joint name="left_wheel_hinge" type="continuous">
    <parent link="base_link"/>
    <child link="left_wheel"/>
    <origin xyz="-0.15 0 0" rpy="0 0 0"/>
    <axis xyz="1 0 0"/>
  </joint>

  <joint name="right_wheel_hinge" type="continuous">
    <parent link="base_link"/>
    <child link="right_wheel"/>
    <origin xyz="0.15 0 0" rpy="0 0 0"/>
    <axis xyz="1 0 0"/>
  </joint>


  <joint name="caster_joint" type="fixed">
    <parent link="base_link"/>
    <child link="caster_wheel"/>
    <origin xyz="0 0.2 -0.05" rpy="0 0 0"/>
  </joint>

</robot>
